Workbook
Name Agata_Bag: #REF!
Name Tshirt: #REF!
Name MARKETING: #REF!
Name Annie_Bag_Silk: #REF!
Name Charm_Bon.VI_x_AMI: #REF!
Name Airpods_Case_Con_Moschettone: #REF!
Name OPEX: #REF!
Name Annie_Bag_Pailletes_Con_Catena: #REF!
Name Annie_Bag_Pailletes: #REF!
Name Lea_Bag: #REF!
Name Annie_Bag_Pailletes_Con_Catena: #REF!
Name MARKETING: #REF!
Name A1A250: PRODUCT_MAP!$A$1
Name LOGISTICA: #REF!
Name Clessidra_Bag: #REF!
Name Valentina_Bag: #REF!
Name LOGISTICA: #REF!
Name Airpods_Case_Con_Moschettone: #REF!
Name Annie_Bag_Pailletes: #REF!
Name Lea_Bag: #REF!
Name Charm_Bon.VI_x_AMI: #REF!
Name Valentina_Bag: #REF!
Name Lola_Bag: #REF!
Name Tshirt: #REF!
Name Clessidra_Bag: #REF!
Name Agata_Bag: #REF!
Name Annie_Bag_Silk: #REF!
Name Lola_Bag: #REF!
Name OPEX: #REF!

Sheet ISTRUZIONI
A1: Conta fisica inventario Amimi
A2: Dati di riferimento aggiornati allo snapshot del 2026-06-16 03:27 (gestionale + Shopify).
A4: Come si compila il foglio CONTA (Benedetta / Ginny):
A5: Per ogni prodotto vedete gia': quante DOVREBBERO essercene (gestionale), quante sono CARICATE online (Shopify) e lo STATO su Shopify (ACTIVE = pubblicata, DRAFT = bozza).
A6: Contate i pezzi reali e scriveteli nella colonna gialla PEZZI CONTATI (scrivete 0 se finiti). Usate NOTE per qualsiasi cosa strana (difettoso, in showroom, prestato...).
A7: Le colonne Delta e Azione si compilano da sole: servono ad Ale per la riconciliazione. Voi potete ignorarle.
A8: Non toccate Shopify ne' il gestionale: basta questo file. Poi premete il bottone 🧾 Amimì > Registra conta.
A10: Le colonne, in breve:
A11: Dovrebbero essere = giacenza calcolata dal gestionale oggi. Caricate online = pezzi mostrati sul sito. Stato Shopify = ACTIVE/DRAFT/assente.
A12: Delta = contati meno dovrebbero. Negativo = mancano pezzi (Ale aggiunge righe in GIFT_OFFLINE). Positivo = trovati in piu' (riga ACQUISTI).
A14: NB: i numeri di riferimento sono dello snapshot 2026-06-16 03:27. Se la conta slitta di giorni, ripremete "Prepara foglio conta" per rigenerarli.

Sheet B2B_NEGOZI
A1: NOME | B1: CITTA | C1: CONTATTO | D1: TIPO_DEAL | E1: PERC_COMMISSIONE | F1: FEE_FISSA | G1: FEE_FREQUENZA | H1: DATA_INIZIO | I1: DATA_FINE | J1: STATO | K1: NOTE
A2: Test_Scheda_QA | B2: Milano | C2: QA Test | D2: commissione | E2: 0.35 | G2: settimana | J2: attivo | K2: TEST FASE D - perc modificata a 35

Sheet DB_B2B
A1: DATA | B1: ANNO | C1: MESE | D1: CODICE | E1: QUANTITA | F1: MODELLO | G1: TIPO_MOVIMENTO | H1: NEGOZIO | I1: PREZZO_RETAIL | J1: PERC_NEGOZIO | K1: RETAIL_TOT | L1: QUOTA_NEGOZIO | M1: INCASSO_AMIMI | N1: COGS | O1: NOTE | P1: MOV_ID | Q1: STATO
A2: 46192.625 | B2: {=IF(A2:A1015="","",YEAR(A2:A1015))} -> 2026 | C2: {=IF(A2:A1015="","",MONTH(A2:A1015))} -> 6 | D2: Nina_Bag_Maxi_STRIPES_REED | E2: 1 | F2: wholesale | G2: venduto | H2: Como | I2: 70 | J2: 0.5 | K2: {=IF(I2:I1015="","",I2:I1015*E2:E1015)} -> 70 | L2: {=IF(I2:I1015="","",K2:K1015*J2:J1015)} -> 35 | M2: {=IF(I2:I1015="","",K2:K1015-L2:L1015)} -> 35 | N2: {=IF(D2:D1015="","",E2:E1015*IFERROR(VLOOKUP(D2:D1015,'PRODUCT_COGS&PRICE'!$A:$E,5,FALSE),0))} -> 14.58 | O2: TEST B2B (alta giacenza, no rischio)
A3: 46192.625 | B3: 2026 | C3: 6 | D3: Nina_Bag_STRIPES_PETROL_BLUE | E3: 1 | F3: wholesale | G3: venduto | H3: Levanto | I3: 50 | J3: 0.5 | K3: 50 | L3: 25 | M3: 25 | N3: 10.71 | O3: TEST B2B (alta giacenza, no rischio)
A1001: 46193.625 | B1001: 2026 | C1001: 6 | D1001: Agata_Bag_FLORAL_DUSTY_PINK_EMBROIDERY | E1001: 1 | F1001: conto_vendita | G1001: invio | H1001: Como | I1001: 80 | J1001: 0.4 | K1001: 80 | L1001: 32 | M1001: 48 | N1001: 19 | P1001: Gsmqoaeldusxno-0
A1002: 46193.625 | B1002: 2026 | C1002: 6 | D1002: Nina_Bag_Maxi_STRIPES_REED | E1002: 3 | F1002: conto_vendita | G1002: invio | H1002: TEST_NEGOZIO_QA | I1002: 100 | J1002: 0.4 | K1002: 300 | L1002: 120 | M1002: 180 | N1002: 43.74 | P1002: GqaInvioA-0 | Q1002: annullato
A1003: 46193.625 | B1003: 2026 | C1003: 6 | D1003: Nina_Bag_Maxi_STRIPES_REED | E1003: 1 | F1003: conto_vendita | G1003: venduto | H1003: TEST_NEGOZIO_QA | I1003: 100 | J1003: 0.4 | K1003: 100 | L1003: 40 | M1003: 60 | N1003: 14.58 | P1003: GqaVendA-0
A1004: 46193.625 | B1004: 2026 | C1004: 6 | D1004: Nina_Bag_Maxi_STRIPES_REED | E1004: 1 | F1004: conto_vendita | G1004: reso | H1004: TEST_NEGOZIO_QA | I1004: 100 | J1004: 0.4 | K1004: 100 | L1004: 40 | M1004: 60 | N1004: 14.58 | P1004: GqaResoA-0
A1005: 46193.625 | B1005: 2026 | C1005: 6 | D1005: Nina_Bag_STRIPES_PETROL_BLUE | E1005: 2 | F1005: wholesale | G1005: venduto | H1005: TEST_NEGOZIO_QA | I1005: 50 | J1005: 0 | K1005: 100 | L1005: 0 | M1005: 100 | N1005: 21.42 | P1005: GqaWholeB-0
A1006: 46195.625 | B1006: 2026 | C1006: 6 | D1006: Agata_Bag_FLORAL_BORDEAUX_EMBROIDERY | E1006: 1 | F1006: wholesale | G1006: venduto | H1006: ZZ_TEST_NUOVO_2306 | I1006: 80 | J1006: 0 | K1006: 80 | L1006: 0 | M1006: 80 | N1006: 19 | O1006: test casi reali | P1006: Gwsnuovo2306-0 | Q1006: annullato
A1007: 46195.625 | B1007: 2026 | C1007: 6 | D1007: Agata_Bag_FLORAL_BORDEAUX_EMBROIDERY | E1007: 2 | F1007: conto_vendita | G1007: invio | H1007: ZZ_TEST_CONTO_2306 | I1007: 160 | J1007: 0.4 | K1007: 320 | L1007: 128 | M1007: 192 | N1007: 38 | O1007: test conto nuovo | P1007: Gcontonuovo2306-0 | Q1007: annullato
A1008: 46195.625 | B1008: 2026 | C1008: 6 | D1008: Agata_Bag_FLORAL_BORDEAUX_EMBROIDERY | E1008: 5 | F1008: conto_vendita | G1008: invio | H1008: ZZ_MATRIX_2306 | I1008: 160 | J1008: 0.4 | K1008: 800 | L1008: 320 | M1008: 480 | N1008: 95 | O1008: matrix | P1008: Gmx_invio-0 | Q1008: annullato
A1009: 46195.625 | B1009: 2026 | C1009: 6 | D1009: Agata_Bag_FLORAL_BORDEAUX_EMBROIDERY | E1009: 2 | F1009: conto_vendita | G1009: venduto | H1009: ZZ_MATRIX_2306 | I1009: 160 | J1009: 0.4 | K1009: 320 | L1009: 128 | M1009: 192 | N1009: 38 | O1009: matrix | P1009: Gmx_vend-0 | Q1009: annullato
A1010: 46195.625 | B1010: 2026 | C1010: 6 | D1010: Agata_Bag_FLORAL_BORDEAUX_EMBROIDERY | E1010: 1 | F1010: conto_vendita | G1010: reso | H1010: ZZ_MATRIX_2306 | I1010: 160 | J1010: 0.4 | K1010: 160 | L1010: 64 | M1010: 96 | N1010: 19 | O1010: matrix | P1010: Gmx_reso-0 | Q1010: annullato
A1011: 46156.625 | B1011: 2026 | C1011: 5 | D1011: Agata_Bag_FLORAL_BORDEAUX_EMBROIDERY | E1011: 1 | F1011: conto_vendita | G1011: invio | H1011: ZZ_MATRIX_2306 | I1011: 160 | J1011: 0.4 | K1011: 160 | L1011: 64 | M1011: 96 | N1011: 19 | O1011: backdate | P1011: Gmx_back-0 | Q1011: annullato
A1012: 46182.625 | B1012: 2026 | C1012: 6 | D1012: Agata_Bag_FLORAL_BORDEAUX_EMBROIDERY | E1012: 1 | F1012: conto_vendita | G1012: invio | H1012: ZZ_BK_2306 | I1012: 160 | J1012: 0.4 | K1012: 160 | L1012: 64 | M1012: 96 | N1012: 19 | O1012: backdate recente | P1012: Gmx_bk2-0 | Q1012: annullato
A1013: 46182.625 | B1013: 2026 | C1013: 6 | D1013: Agata_Bag_FLORAL_BORDEAUX_EMBROIDERY | E1013: 1 | F1013: conto_vendita | G1013: invio | H1013: ZZ_TZ_2306 | I1013: 160 | J1013: 0.4 | K1013: 160 | L1013: 64 | M1013: 96 | N1013: 19 | O1013: tz fix test | P1013: Gtz_fix1-0 | Q1013: annullato
A1014: 46183.125 | B1014: 2026 | C1014: 6 | D1014: Agata_Bag_FLORAL_BORDEAUX_EMBROIDERY | E1014: 1 | F1014: conto_vendita | G1014: invio | H1014: ZZ_TZ_2306 | I1014: 160 | J1014: 0.4 | K1014: 160 | L1014: 64 | M1014: 96 | N1014: 19 | O1014: tz fix2 | P1014: Gtz_fix2-0 | Q1014: annullato
A1015: 46196.125 | B1015: 2026 | C1015: 6 | D1015: Agata_Bag_FLORAL_BORDEAUX_EMBROIDERY | E1015: 1 | F1015: conto_vendita | G1015: invio | H1015: ZZ_TZ_2306 | I1015: 160 | J1015: 0.4 | K1015: 160 | L1015: 64 | M1015: 96 | N1015: 19 | O1015: oggi | P1015: Gtz_fix3-0 | Q1015: annullato

Sheet VARIANT_SYNC_LOG
A1: Timestamp | B1: Type | C1: Order_ID | D1: Detail
A2: 46172.551 | B2: BUILD_MAP | D2: 21 ACTIVE+published 2-variant Catena bags written
A3: 46172.568 | B3: BUILD_MAP | D3: 21 ACTIVE+published 2-variant Catena bags written
A4: 46172.585 | B4: FULL_SYNC | D4: Full sync: 0/21 OK | Errors: | AGATA BAG FLORAL BORDEAUX EMBROIDERY: [{"field":["input","ignoreCompareQuantity"],"message":"The compareQuantity argument must be given to each quantity or ignored using ignoreCompareQuantity."}] | AGATA BAG FLORAL DUSTY PINK EMBROIDERY: [{"field":["input","ignoreCompareQuantity"],"message":"The compareQuantity argument must be given to each quantity or ignored using ignoreCompareQuantity."}] | AGATA BAG FLORAL GREEN EMBROIDERY: [{"field":["input","ignoreCompareQuantity"],"message":"The compareQuantity argument must be given to each quantity or ignored using ignoreCompareQuantity."}] | AGATA BAG FLORAL ORANGE EMBROIDERY: [{"field":["input","ignoreCompareQuantity"],"message":"The compareQuantity argument must be given to each quantity or ignored using ignoreCompareQuantity."}] | AGATA BAG FLORAL PINK EMBROIDERY: [{"field":["input","ignoreCompareQuantity"],"message":"The compareQuantity argument must be given to each quantity or ignored using ignoreCompareQuantity."}] | AGATA BAG PAILLETTES PINK: [{"field":["input","ignoreCompareQuantity"],"message":"The compareQuantity argument must be given to each quantity or ignored using ignoreCompareQuantity."}] | AGATA BAG ROSE BLUE: [{"field":["input","ignoreCompareQuantity"],"message":"The compareQuantity argument must be given to each quantity or ignored using ignoreCompareQuantity."}] | AGATA BAG ROSE BUTTER: [{"field":["input","ignoreCompareQuantity"],"message":"The compareQuantity argument must be given to each quantity or ignored using ignoreCompareQuantity."}] | AGATA BAG ROSE PINK: [{"field":["input","ignoreCompareQuantity"],"message":"The compareQuantity argument must be given to each quantity or ignored using ignoreCompareQuantity."}] | AGATA BAG TIE DYE ORANGE: [{"field":["input","ignoreCompareQuantity"],"message":"The compareQuantity argument must be given to each quantity or ignored using ignoreCompareQuantity."}] | AGATA BAG TIE DYE PINK: [{"field":["input","ignoreCompareQuantity"],"message":"The compareQuantity argument must be given to each quantity or ignored using ignoreCompareQuantity."}] | ANNIE BAG BLUE: [{"field":["input","ignoreCompareQuantity"],"message":"The compareQuantity argument must be given to each quantity or ignored using ignoreCompareQuantity."}] | ANNIE BAG BROWN: [{"field":["input","ignoreCompareQuantity"],"message":"The compareQuantity argument must be given to each quantity or ignored using ignoreCompareQuantity."}] | ANNIE BAG LILAC: [{"field":["input","ignoreCompareQuantity"],"message":"The compareQuantity argument must be given to each quantity or ignored using ignoreCompareQuantity."}] | ANNIE BAG PAILLETTES LIGHT BLUE: [{"field":["input","ignoreCompareQuantity"],"message":"The compareQuantity argument must be given to each quantity or ignored using ignoreCompareQuantity."}] | ANNIE BAG PAILLETTES LIGHT GREEN: [{"field":["input","ignoreCompareQuantity"],"message":"The compareQuantity argument must be given to each quantity or ignored using ignoreCompareQuantity."}] | ANNIE BAG PAILLETTES NUDE: [{"field":["input","ignoreCompareQuantity"],"message":"The compareQuantity argument must be given to each quantity or ignored using ignoreCompareQuantity."}] | ANNIE BAG PAILLETTES PINK: [{"field":["input","ignoreCompareQuantity"],"message":"The compareQuantity argument must be given to each quantity or ignored using ignoreCompareQuantity."}] | ANNIE BAG PEARL GREY: [{"field":["input","ignoreCompareQuantity"],"message":"The compareQuantity argument must be given to each quantity or ignored using ignoreCompareQuantity."}] | ANNIE BAG PINK: [{"field":["input","ignoreCompareQuantity"],"message":"The compareQuantity argument must be given to each quantity or ignored using ignoreCompareQuantity."}] | ANNIE BAG STRIPES PINK: [{"field":["input","ignoreCompareQuantity"],"message":"The compareQuantity argument must be given to each quantity or ignored using ignoreCompareQuantity."}]
A5: 46172.585 | B5: WEBHOOK_REGISTER | D5: Registered orders/create webhook gid://shopify/WebhookSubscription/2221675708743 URL: https://script.google.com/macros/s/AKfycbzi1GmsPGj4qFeHiTPZVaj3K5ZgSjuWUqRQPd_v2tE3D9FPXSzOA17nDAYbxwdeurWXKQ/exec?token=1cf735f7-79ac-4a73-aea1-0df461dac6e5
A6: 46172.591 | B6: FULL_SYNC | D6: Full sync: 21/21 OK
A7: 46172.598 | B7: SYNCED | C7: 9999000001 | D7: AGATA BAG ROSE PINK -1 -> 3
A8: 46172.602 | B8: RESTOCK | D8: AGATA BAG ROSE PINK -> 4
A9: 46172.973 | B9: DAILY_REPORT | D9: risk=7 drift=0
A10: 46173.445 | B10: NO_MATCH | C10: 7786211606855 | D10: No Catena-pair bags in this order
A11: 46173.445 | B11: DUPLICATE | C11: 7786211606855 | D11: Already processed, skipped
A12: 46173.446 | B12: DUPLICATE | C12: 7786211606855 | D12: Already processed, skipped
A13: 46173.447 | B13: DUPLICATE | C13: 7786211606855 | D13: Already processed, skipped
A14: 46173.451 | B14: DUPLICATE | C14: 7786211606855 | D14: Already processed, skipped
A15: 46173.466 | B15: DUPLICATE | C15: 7786211606855 | D15: Already processed, skipped
A16: 46173.487 | B16: DUPLICATE | C16: 7786211606855 | D16: Already processed, skipped
A17: 46173.528 | B17: DUPLICATE | C17: 7786211606855 | D17: Already processed, skipped
A18: 46173.554 | B18: SYNCED | C18: 7786725081415 | D18: AGATA BAG FLORAL GREEN EMBROIDERY -1 -> 0; AGATA BAG FLORAL PINK EMBROIDERY -1 -> 3
A19: 46173.554 | B19: DUPLICATE | C19: 7786725081415 | D19: Already processed, skipped
A20: 46173.555 | B20: DUPLICATE | C20: 7786725081415 | D20: Already processed, skipped
A21: 46173.557 | B21: DUPLICATE | C21: 7786725081415 | D21: Already processed, skipped
... A31: 46173.973 | B31: DUPLICATE | C31: 7787347968327 | D31: Already processed, skipped
A32: 46173.973 | B32: DAILY_REPORT | D32: risk=6 drift=0
A33: 46173.977 | B33: DUPLICATE | C33: 7787347968327 | D33: Already processed, skipped
A34: 46173.992 | B34: DUPLICATE | C34: 7787347968327 | D34: Already processed, skipped
A35: 46174.013 | B35: DUPLICATE | C35: 7787347968327 | D35: Already processed, skipped
A36: 46174.055 | B36: DUPLICATE | C36: 7787347968327 | D36: Already processed, skipped
A37: 46174.117 | B37: NO_MATCH | C37: 7787787419975 | D37: No Catena-pair bags in this order
A38: 46174.117 | B38: DUPLICATE | C38: 7787787419975 | D38: Already processed, skipped
A39: 46174.118 | B39: DUPLICATE | C39: 7787787419975 | D39: Already processed, skipped
A40: 46174.119 | B40: DUPLICATE | C40: 7787787419975 | D40: Already processed, skipped
A41: 46174.123 | B41: DUPLICATE | C41: 7787787419975 | D41: Already processed, skipped
A42: 46174.138 | B42: DUPLICATE | C42: 7787347968327 | D42: Already processed, skipped
A43: 46174.138 | B43: DUPLICATE | C43: 7787787419975 | D43: Already processed, skipped
A44: 46174.159 | B44: DUPLICATE | C44: 7787787419975 | D44: Already processed, skipped
... A91: 46174.417 | B91: DUPLICATE | C91: 7788252725575 | D91: Already processed, skipped
A92: 46174.973 | B92: DAILY_REPORT | D92: risk=7 drift=1
A93: 46175.051 | B93: NO_MATCH | C93: 7790371373383 | D93: No Catena-pair bags in this order
A94: 46175.051 | B94: DUPLICATE | C94: 7790371373383 | D94: Already processed, skipped
A95: 46175.052 | B95: DUPLICATE | C95: 7790371373383 | D95: Already processed, skipped
...

Sheet CONTA_INBOX
A1: timestamp | B1: data_conta | C1: CODICE | D1: modello | E1: variante | F1: contati | G1: giac_oggi | H1: delta | I1: chi | J1: nota | K1: stato
A2: 46189.141 | B2: 46189 | C2: Lea_Bag_COCCO_BLACK | D2: Lea Bag | E2: COCCO BLACK | F2: 3 | G2: 8 | H2: -5 | I2: cofounder | J2: | ammanco 5 >= soglia 3: serve indagine sulla causa | K2: ignorato (test 16-06)
A3: 46189.141 | B3: 46189 | C3: Lea_Bag_Zebra_Dark | D3: Lea Bag | E3: Zebra Dark | F3: 8 | G3: 6 | H3: 2 | I3: cofounder | J3: | surplus +2: possibile acquisto mancante / reso / errore conta (decisione umana) | K3: ignorato (test 16-06)

Sheet CONTA_INPUT
A1: Modello | B1: Variante / Descrizione | C1: CODICE_AMIIMI | D1: Dovrebbero essere (gestionale) | E1: Caricate online (Shopify) | F1: Stato Shopify | G1: PEZZI CONTATI | H1: Delta (contati - gestionale) | I1: Azione suggerita | J1: NOTE | K1: CONTA_APPLICATA
A2: Lea Bag | B2: LEOPARDO SAVANA | C2: Lea_Bag_LEOPARDO_SAVANA | D2: 8 | E2: 8 | F2: ACTIVE | H2: =IF(G2="","",G2-D2) | I2: =IF(G2="","Non ancora contato",IF(G2-D2=0,"OK",IF(G2-D2<0,IF(ABS(G2-D2)<3,"Rettifica -"&ABS(G2-D2)&" (GIFT_OFFLINE)","DA VERIFICARE: ammanco "&ABS(G2-D2)),"DA VERIFICARE: surplus +"&(G2-D2)))) -> Non ancora contato
A3: Lea Bag | B3: COCCO BLACK | C3: Lea_Bag_COCCO_BLACK | D3: 8 | E3: 8 | F3: ACTIVE | H3: =IF(G3="","",G3-D3) | I3: =IF(G3="","Non ancora contato",IF(G3-D3=0,"OK",IF(G3-D3<0,IF(ABS(G3-D3)<3,"Rettifica -"&ABS(G3-D3)&" (GIFT_OFFLINE)","DA VERIFICARE: ammanco "&ABS(G3-D3)),"DA VERIFICARE: surplus +"&(G3-D3)))) -> Non ancora contato
A4: Lea Bag | B4: Zebra Dark | C4: Lea_Bag_Zebra_Dark | D4: 6 | E4: 6 | F4: ACTIVE | H4: =IF(G4="","",G4-D4) | I4: =IF(G4="","Non ancora contato",IF(G4-D4=0,"OK",IF(G4-D4<0,IF(ABS(G4-D4)<3,"Rettifica -"&ABS(G4-D4)&" (GIFT_OFFLINE)","DA VERIFICARE: ammanco "&ABS(G4-D4)),"DA VERIFICARE: surplus +"&(G4-D4)))) -> Non ancora contato
A5: Lea Bag | B5: PONY COCCO BLACK | C5: Lea_Bag_PONY_COCCO_BLACK | D5: 0 | E5: 0 | F5: ACTIVE | H5: =IF(G5="","",G5-D5) | I5: =IF(G5="","Non ancora contato",IF(G5-D5=0,"OK",IF(G5-D5<0,IF(ABS(G5-D5)<3,"Rettifica -"&ABS(G5-D5)&" (GIFT_OFFLINE)","DA VERIFICARE: ammanco "&ABS(G5-D5)),"DA VERIFICARE: surplus +"&(G5-D5)))) -> Non ancora contato
A6: Lea Bag | B6: JUNGLE | C6: Lea_Bag_JUNGLE | D6: 1 | E6: 0 | F6: DRAFT | H6: =IF(G6="","",G6-D6) | I6: =IF(G6="","Non ancora contato",IF(G6-D6=0,"OK",IF(G6-D6<0,IF(ABS(G6-D6)<3,"Rettifica -"&ABS(G6-D6)&" (GIFT_OFFLINE)","DA VERIFICARE: ammanco "&ABS(G6-D6)),"DA VERIFICARE: surplus +"&(G6-D6)))) -> Non ancora contato
A7: Lea Bag | B7: GREEN MILITARY | C7: Lea_Bag_GREEN_MILITARY | D7: 1 | E7: 1 | F7: ACTIVE | H7: =IF(G7="","",G7-D7) | I7: =IF(G7="","Non ancora contato",IF(G7-D7=0,"OK",IF(G7-D7<0,IF(ABS(G7-D7)<3,"Rettifica -"&ABS(G7-D7)&" (GIFT_OFFLINE)","DA VERIFICARE: ammanco "&ABS(G7-D7)),"DA VERIFICARE: surplus +"&(G7-D7)))) -> Non ancora contato
A8: Lea Bag | B8: KAKI GREEN PONY | C8: Lea_Bag_KAKI_GREEN_PONY | D8: 1 | E8: 0 | F8: ACTIVE | H8: =IF(G8="","",G8-D8) | I8: =IF(G8="","Non ancora contato",IF(G8-D8=0,"OK",IF(G8-D8<0,IF(ABS(G8-D8)<3,"Rettifica -"&ABS(G8-D8)&" (GIFT_OFFLINE)","DA VERIFICARE: ammanco "&ABS(G8-D8)),"DA VERIFICARE: surplus +"&(G8-D8)))) -> Non ancora contato
A9: Lea Bag | B9: Cavallino Chocolate | C9: Lea_Bag_Cavallino_Chocolate | D9: 1 | E9: n/d | F9: n/d | H9: =IF(G9="","",G9-D9) | I9: =IF(G9="","Non ancora contato",IF(G9-D9=0,"OK",IF(G9-D9<0,IF(ABS(G9-D9)<3,"Rettifica -"&ABS(G9-D9)&" (GIFT_OFFLINE)","DA VERIFICARE: ammanco "&ABS(G9-D9)),"DA VERIFICARE: surplus +"&(G9-D9)))) -> Non ancora contato
A10: Lea Bag | B10: Cavallino Light Brown | C10: Lea_Bag_Cavallino_Light_Brown | D10: 1 | E10: 1 | F10: ACTIVE | H10: =IF(G10="","",G10-D10) | I10: =IF(G10="","Non ancora contato",IF(G10-D10=0,"OK",IF(G10-D10<0,IF(ABS(G10-D10)<3,"Rettifica -"&ABS(G10-D10)&" (GIFT_OFFLINE)","DA VERIFICARE: ammanco "&ABS(G10-D10)),"DA VERIFICARE: surplus +"&(G10-D10)))) -> Non ancora contato
A11: Lea Bag | B11: Cavallino Bordeaux | C11: Lea_Bag_Cavallino_Bordeaux | D11: 2 | E11: n/d | F11: n/d | H11: =IF(G11="","",G11-D11) | I11: =IF(G11="","Non ancora contato",IF(G11-D11=0,"OK",IF(G11-D11<0,IF(ABS(G11-D11)<3,"Rettifica -"&ABS(G11-D11)&" (GIFT_OFFLINE)","DA VERIFICARE: ammanco "&ABS(G11-D11)),"DA VERIFICARE: surplus +"&(G11-D11)))) -> Non ancora contato
A12: Lea Bag | B12: ESPRESSO PONY | C12: Lea_Bag_ESPRESSO_PONY | D12: 0 | E12: 0 | F12: DRAFT | H12: =IF(G12="","",G12-D12) | I12: =IF(G12="","Non ancora contato",IF(G12-D12=0,"OK",IF(G12-D12<0,IF(ABS(G12-D12)<3,"Rettifica -"&ABS(G12-D12)&" (GIFT_OFFLINE)","DA VERIFICARE: ammanco "&ABS(G12-D12)),"DA VERIFICARE: surplus +"&(G12-D12)))) -> Non ancora contato
A13: Lea Bag | B13: BLACK | C13: Lea_Bag_BLACK | D13: 2 | E13: 1 | F13: ACTIVE | H13: =IF(G13="","",G13-D13) | I13: =IF(G13="","Non ancora contato",IF(G13-D13=0,"OK",IF(G13-D13<0,IF(ABS(G13-D13)<3,"Rettifica -"&ABS(G13-D13)&" (GIFT_OFFLINE)","DA VERIFICARE: ammanco "&ABS(G13-D13)),"DA VERIFICARE: surplus +"&(G13-D13)))) -> Non ancora contato
A14: Maria Bag | B14: Red | C14: Maria_Bag_Red | D14: 0 | E14: 0 | F14: DRAFT | H14: =IF(G14="","",G14-D14) | I14: =IF(G14="","Non ancora contato",IF(G14-D14=0,"OK",IF(G14-D14<0,IF(ABS(G14-D14)<3,"Rettifica -"&ABS(G14-D14)&" (GIFT_OFFLINE)","DA VERIFICARE: ammanco "&ABS(G14-D14)),"DA VERIFICARE: surplus +"&(G14-D14)))) -> Non ancora contato
A15: Maria Bag | B15: RED PIERCING | C15: Maria_Bag_RED_PIERCING | D15: 4 | E15: 4 | F15: ACTIVE | H15: =IF(G15="","",G15-D15) | I15: =IF(G15="","Non ancora contato",IF(G15-D15=0,"OK",IF(G15-D15<0,IF(ABS(G15-D15)<3,"Rettifica -"&ABS(G15-D15)&" (GIFT_OFFLINE)","DA VERIFICARE: ammanco "&ABS(G15-D15)),"DA VERIFICARE: surplus +"&(G15-D15)))) -> Non ancora contato
A16: Valentina Bag | B16: CHOCOLATE | C16: Valentina_Bag_CHOCOLATE | D16: 21 | E16: 8 | F16: ACTIVE | H16: =IF(G16="","",G16-D16) | I16: =IF(G16="","Non ancora contato",IF(G16-D16=0,"OK",IF(G16-D16<0,IF(ABS(G16-D16)<3,"Rettifica -"&ABS(G16-D16)&" (GIFT_OFFLINE)","DA VERIFICARE: ammanco "&ABS(G16-D16)),"DA VERIFICARE: surplus +"&(G16-D16)))) -> Non ancora contato
A17: Nina Bag | B17: Stripes Strawberry | C17: Nina_Bag_Stripes_Strawberry | D17: 21 | E17: 19 | F17: ACTIVE | H17: =IF(G17="","",G17-D17) | I17: =IF(G17="","Non ancora contato",IF(G17-D17=0,"OK",IF(G17-D17<0,IF(ABS(G17-D17)<3,"Rettifica -"&ABS(G17-D17)&" (GIFT_OFFLINE)","DA VERIFICARE: ammanco "&ABS(G17-D17)),"DA VERIFICARE: surplus +"&(G17-D17)))) -> Non ancora contato
A18: Nina Bag | B18: PEACH | C18: Nina_Bag_PEACH | D18: 24 | E18: 22 | F18: ACTIVE | H18: =IF(G18="","",G18-D18) | I18: =IF(G18="","Non ancora contato",IF(G18-D18=0,"OK",IF(G18-D18<0,IF(ABS(G18-D18)<3,"Rettifica -"&ABS(G18-D18)&" (GIFT_OFFLINE)","DA VERIFICARE: ammanco "&ABS(G18-D18)),"DA VERIFICARE: surplus +"&(G18-D18)))) -> Non ancora contato
A19: Nina Bag | B19: Checks Navy Blue | C19: Nina_Bag_Checks_Navy_Blue | D19: 22 | E19: 20 | F19: ACTIVE | H19: =IF(G19="","",G19-D19) | I19: =IF(G19="","Non ancora contato",IF(G19-D19=0,"OK",IF(G19-D19<0,IF(ABS(G19-D19)<3,"Rettifica -"&ABS(G19-D19)&" (GIFT_OFFLINE)","DA VERIFICARE: ammanco "&ABS(G19-D19)),"DA VERIFICARE: surplus +"&(G19-D19)))) -> Non ancora contato
A20: Nina Bag | B20: Stripes Mint | C20: Nina_Bag_Stripes_Mint | D20: 5 | E20: 3 | F20: ACTIVE | H20: =IF(G20="","",G20-D20) | I20: =IF(G20="","Non ancora contato",IF(G20-D20=0,"OK",IF(G20-D20<0,IF(ABS(G20-D20)<3,"Rettifica -"&ABS(G20-D20)&" (GIFT_OFFLINE)","DA VERIFICARE: ammanco "&ABS(G20-D20)),"DA VERIFICARE: surplus +"&(G20-D20)))) -> Non ancora contato
A21: Lea Bag | B21: BLACK WHITE PONY | C21: Lea_Bag_BLACK_WHITE_PONY | D21: 0 | E21: 0 | F21: DRAFT | H21: =IF(G21="","",G21-D21) | I21: =IF(G21="","Non ancora contato",IF(G21-D21=0,"OK",IF(G21-D21<0,IF(ABS(G21-D21)<3,"Rettifica -"&ABS(G21-D21)&" (GIFT_OFFLINE)","DA VERIFICARE: ammanco "&ABS(G21-D21)),"DA VERIFICARE: surplus +"&(G21-D21)))) -> Non ancora contato
A22: Lea Bag | B22: RED PATENT | C22: Lea_Bag_RED_PATENT | D22: 8 | E22: 8 | F22: ACTIVE | H22: =IF(G22="","",G22-D22) | I22: =IF(G22="","Non ancora contato",IF(G22-D22=0,"OK",IF(G22-D22<0,IF(ABS(G22-D22)<3,"Rettifica -"&ABS(G22-D22)&" (GIFT_OFFLINE)","DA VERIFICARE: ammanco "&ABS(G22-D22)),"DA VERIFICARE: surplus +"&(G22-D22)))) -> Non ancora contato
A23: Lea Bag | B23: BLUE ELECTRIC | C23: Lea_Bag_BLUE_ELECTRIC | D23: 0 | E23: 0 | F23: DRAFT | H23: =IF(G23="","",G23-D23) | I23: =IF(G23="","Non ancora contato",IF(G23-D23=0,"OK",IF(G23-D23<0,IF(ABS(G23-D23)<3,"Rettifica -"&ABS(G23-D23)&" (GIFT_OFFLINE)","DA VERIFICARE: ammanco "&ABS(G23-D23)),"DA VERIFICARE: surplus +"&(G23-D23)))) -> Non ancora contato
... A30: Lea Bag | B30: VERNICE PURPLE PATENT | C30: Lea_Bag_VERNICE_PURPLE_PATENT | D30: 4 | E30: 2 | F30: ACTIVE | H30: =IF(G30="","",G30-D30) | I30: =IF(G30="","Non ancora contato",IF(G30-D30=0,"OK",IF(G30-D30<0,IF(ABS(G30-D30)<3,"Rettifica -"&ABS(G30-D30)&" (GIFT_OFFLINE)","DA VERIFICARE: ammanco "&ABS(G30-D30)),"DA VERIFICARE: surplus +"&(G30-D30)))) -> Non ancora contato
A31: Lea Bag | B31: TOASTED LEATHER GREEN | C31: Lea_Bag_TOASTED_LEATHER_GREEN | D31: 4 | E31: n/d | F31: n/d | H31: =IF(G31="","",G31-D31) | I31: =IF(G31="","Non ancora contato",IF(G31-D31=0,"OK",IF(G31-D31<0,IF(ABS(G31-D31)<3,"Rettifica -"&ABS(G31-D31)&" (GIFT_OFFLINE)","DA VERIFICARE: ammanco "&ABS(G31-D31)),"DA VERIFICARE: surplus +"&(G31-D31)))) -> Non ancora contato
A32: Lea Bag Maxi | B32: SUEDE CHOCOLATE CHARM | C32: Lea_Bag_Maxi_SUEDE_CHOCOLATE_CHARM | D32: -2 | E32: 0 | F32: ACTIVE | H32: =IF(G32="","",G32-D32) | I32: =IF(G32="","Non ancora contato",IF(G32-D32=0,"OK",IF(G32-D32<0,IF(ABS(G32-D32)<3,"Rettifica -"&ABS(G32-D32)&" (GIFT_OFFLINE)","DA VERIFICARE: ammanco "&ABS(G32-D32)),"DA VERIFICARE: surplus +"&(G32-D32)))) -> Non ancora contato
A33: Lea Bag Maxi | B33: SUEDE CHOCOLATE | C33: Lea_Bag_Maxi_SUEDE_CHOCOLATE | D33: 0 | E33: 0 | F33: ACTIVE | H33: =IF(G33="","",G33-D33) | I33: =IF(G33="","Non ancora contato",IF(G33-D33=0,"OK",IF(G33-D33<0,IF(ABS(G33-D33)<3,"Rettifica -"&ABS(G33-D33)&" (GIFT_OFFLINE)","DA VERIFICARE: ammanco "&ABS(G33-D33)),"DA VERIFICARE: surplus +"&(G33-D33)))) -> Non ancora contato
A34: Lea Bag Maxi | B34: COCCO BLACK | C34: Lea_Bag_Maxi_COCCO_BLACK | D34: 6 | E34: 6 | F34: ACTIVE | H34: =IF(G34="","",G34-D34) | I34: =IF(G34="","Non ancora contato",IF(G34-D34=0,"OK",IF(G34-D34<0,IF(ABS(G34-D34)<3,"Rettifica -"&ABS(G34-D34)&" (GIFT_OFFLINE)","DA VERIFICARE: ammanco "&ABS(G34-D34)),"DA VERIFICARE: surplus +"&(G34-D34)))) -> Non ancora contato
A35: Valentina Bag | B35: RED | C35: Valentina_Bag_RED | D35: 15 | E35: 6 | F35: ACTIVE | H35: =IF(G35="","",G35-D35) | I35: =IF(G35="","Non ancora contato",IF(G35-D35=0,"OK",IF(G35-D35<0,IF(ABS(G35-D35)<3,"Rettifica -"&ABS(G35-D35)&" (GIFT_OFFLINE)","DA VERIFICARE: ammanco "&ABS(G35-D35)),"DA VERIFICARE: surplus +"&(G35-D35)))) -> Non ancora contato
A36: Valentina Bag | B36: COCCO BLACK | C36: Valentina_Bag_COCCO_BLACK | D36: 7 | E36: 10 | F36: ACTIVE | H36: =IF(G36="","",G36-D36) | I36: =IF(G36="","Non ancora contato",IF(G36-D36=0,"OK",IF(G36-D36<0,IF(ABS(G36-D36)<3,"Rettifica -"&ABS(G36-D36)&" (GIFT_OFFLINE)","DA VERIFICARE: ammanco "&ABS(G36-D36)),"DA VERIFICARE: surplus +"&(G36-D36)))) -> Non ancora contato
A37: Valentina Bag | B37: GREEN MILITARY | C37: Valentina_Bag_GREEN_MILITARY | D37: 9 | E37: 7 | F37: ACTIVE | H37: =IF(G37="","",G37-D37) | I37: =IF(G37="","Non ancora contato",IF(G37-D37=0,"OK",IF(G37-D37<0,IF(ABS(G37-D37)<3,"Rettifica -"&ABS(G37-D37)&" (GIFT_OFFLINE)","DA VERIFICARE: ammanco "&ABS(G37-D37)),"DA VERIFICARE: surplus +"&(G37-D37)))) -> Non ancora contato
A38: Annie Bag | B38: BROWN | C38: Annie_Bag_BROWN | D38: 0 | E38: 0 | F38: DRAFT | H38: =IF(G38="","",G38-D38) | I38: =IF(G38="","Non ancora contato",IF(G38-D38=0,"OK",IF(G38-D38<0,IF(ABS(G38-D38)<3,"Rettifica -"&ABS(G38-D38)&" (GIFT_OFFLINE)","DA VERIFICARE: ammanco "&ABS(G38-D38)),"DA VERIFICARE: surplus +"&(G38-D38)))) -> Non ancora contato
A39: Annie Bag | B39: PAILLETTES PINK | C39: Annie_Bag_PAILLETTES_PINK | D39: 0 | E39: 0 | F39: ACTIVE | H39: =IF(G39="","",G39-D39) | I39: =IF(G39="","Non ancora contato",IF(G39-D39=0,"OK",IF(G39-D39<0,IF(ABS(G39-D39)<3,"Rettifica -"&ABS(G39-D39)&" (GIFT_OFFLINE)","DA VERIFICARE: ammanco "&ABS(G39-D39)),"DA VERIFICARE: surplus +"&(G39-D39)))) -> Non ancora contato
A40: Annie Bag | B40: BLUE | C40: Annie_Bag_BLUE | D40: 5 | E40: 5 | F40: ACTIVE | H40: =IF(G40="","",G40-D40) | I40: =IF(G40="","Non ancora contato",IF(G40-D40=0,"OK",IF(G40-D40<0,IF(ABS(G40-D40)<3,"Rettifica -"&ABS(G40-D40)&" (GIFT_OFFLINE)","DA VERIFICARE: ammanco "&ABS(G40-D40)),"DA VERIFICARE: surplus +"&(G40-D40)))) -> Non ancora contato
A41: Annie Bag | B41: PINK | C41: Annie_Bag_PINK | D41: 3 | E41: 3 | F41: ACTIVE | H41: =IF(G41="","",G41-D41) | I41: =IF(G41="","Non ancora contato",IF(G41-D41=0,"OK",IF(G41-D41<0,IF(ABS(G41-D41)<3,"Rettifica -"&ABS(G41-D41)&" (GIFT_OFFLINE)","DA VERIFICARE: ammanco "&ABS(G41-D41)),"DA VERIFICARE: surplus +"&(G41-D41)))) -> Non ancora contato
A42: Annie Bag | B42: PAILLETTES GREY | C42: Annie_Bag_PAILLETTES_GREY | D42: 0 | E42: 0 | F42: DRAFT | H42: =IF(G42="","",G42-D42) | I42: =IF(G42="","Non ancora contato",IF(G42-D42=0,"OK",IF(G42-D42<0,IF(ABS(G42-D42)<3,"Rettifica -"&ABS(G42-D42)&" (GIFT_OFFLINE)","DA VERIFICARE: ammanco "&ABS(G42-D42)),"DA VERIFICARE: surplus +"&(G42-D42)))) -> Non ancora contato
A43: Annie Bag | B43: PAILLETTES LIGHT BLUE | C43: Annie_Bag_PAILLETTES_LIGHT_BLUE | D43: 0 | E43: 0 | F43: ACTIVE | H43: =IF(G43="","",G43-D43) | I43: =IF(G43="","Non ancora contato",IF(G43-D43=0,"OK",IF(G43-D43<0,IF(ABS(G43-D43)<3,"Rettifica -"&ABS(G43-D43)&" (GIFT_OFFLINE)","DA VERIFICARE: ammanco "&ABS(G43-D43)),"DA VERIFICARE: surplus +"&(G43-D43)))) -> Non ancora contato
... A54: Annie Bag | B54: PEARL GREY | C54: Annie_Bag_PEARL_GREY | D54: 1 | E54: 1 | F54: ACTIVE | H54: =IF(G54="","",G54-D54) | I54: =IF(G54="","Non ancora contato",IF(G54-D54=0,"OK",IF(G54-D54<0,IF(ABS(G54-D54)<3,"Rettifica -"&ABS(G54-D54)&" (GIFT_OFFLINE)","DA VERIFICARE: ammanco "&ABS(G54-D54)),"DA VERIFICARE: surplus +"&(G54-D54)))) -> Non ancora contato
A55: Lea Bag | B55: Zebra Pony | C55: Lea_Bag_Zebra_Pony | D55: 8 | E55: n/d | F55: n/d | H55: =IF(G55="","",G55-D55) | I55: =IF(G55="","Non ancora contato",IF(G55-D55=0,"OK",IF(G55-D55<0,IF(ABS(G55-D55)<3,"Rettifica -"&ABS(G55-D55)&" (GIFT_OFFLINE)","DA VERIFICARE: ammanco "&ABS(G55-D55)),"DA VERIFICARE: surplus +"&(G55-D55)))) -> Non ancora contato
A56: Lea Bag | B56: COCCO_ORANGE | C56: Lea_Bag_COCCO_ORANGE | D56: 0 | E56: 0 | F56: ACTIVE | H56: =IF(G56="","",G56-D56) | I56: =IF(G56="","Non ancora contato",IF(G56-D56=0,"OK",IF(G56-D56<0,IF(ABS(G56-D56)<3,"Rettifica -"&ABS(G56-D56)&" (GIFT_OFFLINE)","DA VERIFICARE: ammanco "&ABS(G56-D56)),"DA VERIFICARE: surplus +"&(G56-D56)))) -> Non ancora contato
...

Sheet SKU_HISTORY
A1: ts | B1: date | C1: json
A2: 46182.873 | B2: 46182 | C2: {"ts":"2026-06-09 20:57","date":"2026-06-09","total":214,"active":94,"draft":120,"archived":0,"active_instock":77,"active_oos":17,"instock_not_active":5,"var_active_instock":93,"by_line":{"AGATA":{"active":14,"active_instock":8,"active_oos":6},"AIRPODS":{"active":6,"active_instock":6,"active_oos":0},"ANNIE":{"active":11,"active_instock":4,"active_oos":7},"GIFT":{"active":1,"active_instock":0,"active_oos":1},"LAPTOP":{"active":7,"active_instock":7,"active_oos":0},"LEA":{"active":20,"active_instock":17,"active_oos":3},"MARIA":{"active":2,"active_instock":2,"active_oos":0},"MINI":{"active":6,"active_instock":6,"active_oos":0},"NINA":{"active":16,"active_instock":16,"active_oos":0},"SUNGLASS":{"active":6,"active_instock":6,"active_oos":0},"TIGER":{"active":1,"active_instock":1,"active_oos":0},"VALENTINA":{"active":4,"active_instock":4,"active_oos":0}},"by_macro":{"Tessuto":{"active":41,"active_instock":28,"active_oos":13},"Pelle":{"active":26,"active_instock":23,"active_oos":3},"Accessori":{"active":26,"active_instock":26,"active_oos":0},"Altro":{"active":1,"active_instock":0,"active_oos":1}}}
A3: 46182.884 | B3: 46182 | C3: {"ts":"2026-06-09 21:13","date":"2026-06-09","total":214,"active":94,"draft":120,"archived":0,"active_instock":77,"active_oos":17,"instock_not_active":5,"var_active_instock":93,"by_line":{"AGATA":{"active":14,"active_instock":8,"active_oos":6},"AIRPODS":{"active":6,"active_instock":6,"active_oos":0},"ANNIE":{"active":11,"active_instock":4,"active_oos":7},"GIFT":{"active":1,"active_instock":0,"active_oos":1},"LAPTOP":{"active":7,"active_instock":7,"active_oos":0},"LEA":{"active":20,"active_instock":17,"active_oos":3},"MARIA":{"active":2,"active_instock":2,"active_oos":0},"MINI":{"active":6,"active_instock":6,"active_oos":0},"NINA":{"active":16,"active_instock":16,"active_oos":0},"SUNGLASS":{"active":6,"active_instock":6,"active_oos":0},"TIGER":{"active":1,"active_instock":1,"active_oos":0},"VALENTINA":{"active":4,"active_instock":4,"active_oos":0}},"by_macro":{"Tessuto":{"active":41,"active_instock":28,"active_oos":13},"Pelle":{"active":26,"active_instock":23,"active_oos":3},"Accessori":{"active":26,"active_instock":26,"active_oos":0},"Altro":{"active":1,"active_instock":0,"active_oos":1}}}
A4: 46182.919 | B4: 46182 | C4: {"ts":"2026-06-09 22:03","date":"2026-06-09","total":214,"active":94,"draft":120,"archived":0,"active_instock":77,"active_oos":17,"instock_not_active":5,"var_active_instock":93,"by_line":{"AGATA":{"active":14,"active_instock":8,"active_oos":6},"AIRPODS":{"active":6,"active_instock":6,"active_oos":0},"ANNIE":{"active":11,"active_instock":4,"active_oos":7},"GIFT":{"active":1,"active_instock":0,"active_oos":1},"LAPTOP":{"active":7,"active_instock":7,"active_oos":0},"LEA":{"active":20,"active_instock":17,"active_oos":3},"MARIA":{"active":2,"active_instock":2,"active_oos":0},"MINI":{"active":6,"active_instock":6,"active_oos":0},"NINA":{"active":16,"active_instock":16,"active_oos":0},"SUNGLASS":{"active":6,"active_instock":6,"active_oos":0},"TIGER":{"active":1,"active_instock":1,"active_oos":0},"VALENTINA":{"active":4,"active_instock":4,"active_oos":0}},"by_macro":{"Tessuto":{"active":41,"active_instock":28,"active_oos":13},"Pelle":{"active":26,"active_instock":23,"active_oos":3},"Accessori":{"active":26,"active_instock":26,"active_oos":0},"Altro":{"active":1,"active_instock":0,"active_oos":1}}}
A5: 46182.992 | B5: 46182 | C5: {"ts":"2026-06-09 23:48","date":"2026-06-09","total":214,"active":94,"draft":120,"archived":0,"active_instock":79,"active_oos":15,"instock_not_active":5,"var_active_instock":96,"by_line":{"AGATA":{"active":14,"active_instock":8,"active_oos":6},"AIRPODS":{"active":6,"active_instock":6,"active_oos":0},"ANNIE":{"active":11,"active_instock":5,"active_oos":6},"GIFT":{"active":1,"active_instock":0,"active_oos":1},"LAPTOP":{"active":7,"active_instock":7,"active_oos":0},"LEA":{"active":20,"active_instock":18,"active_oos":2},"MARIA":{"active":2,"active_instock":2,"active_oos":0},"MINI":{"active":6,"active_instock":6,"active_oos":0},"NINA":{"active":16,"active_instock":16,"active_oos":0},"SUNGLASS":{"active":6,"active_instock":6,"active_oos":0},"TIGER":{"active":1,"active_instock":1,"active_oos":0},"VALENTINA":{"active":4,"active_instock":4,"active_oos":0}},"by_macro":{"Tessuto":{"active":41,"active_instock":29,"active_oos":12},"Pelle":{"active":26,"active_instock":24,"active_oos":2},"Accessori":{"active":26,"active_instock":26,"active_oos":0},"Altro":{"active":1,"active_instock":0,"active_oos":1}}}
A6: 46183.722 | B6: 46183 | C6: {"ts":"2026-06-10 17:19","date":"2026-06-10","total":214,"active":94,"draft":120,"archived":0,"active_instock":80,"active_oos":14,"instock_not_active":2,"var_active_instock":101,"by_line":{"AGATA":{"active":14,"active_instock":10,"active_oos":4},"AIRPODS":{"active":6,"active_instock":6,"active_oos":0},"ANNIE":{"active":11,"active_instock":7,"active_oos":4},"GIFT":{"active":1,"active_instock":0,"active_oos":1},"LAPTOP":{"active":7,"active_instock":7,"active_oos":0},"LEA":{"active":20,"active_instock":15,"active_oos":5},"MARIA":{"active":2,"active_instock":2,"active_oos":0},"MINI":{"active":6,"active_instock":6,"active_oos":0},"NINA":{"active":16,"active_instock":16,"active_oos":0},"SUNGLASS":{"active":6,"active_instock":6,"active_oos":0},"TIGER":{"active":1,"active_instock":1,"active_oos":0},"VALENTINA":{"active":4,"active_instock":4,"active_oos":0}},"by_macro":{"Tessuto":{"active":41,"active_instock":33,"active_oos":8},"Pelle":{"active":26,"active_instock":21,"active_oos":5},"Accessori":{"active":26,"active_instock":26,"active_oos":0},"Altro":{"active":1,"active_instock":0,"active_oos":1}}}
A7: 46183.928 | B7: 46183 | C7: {"ts":"2026-06-10 22:17","date":"2026-06-10","total":214,"active":94,"draft":120,"archived":0,"active_instock":80,"active_oos":14,"instock_not_active":2,"var_active_instock":101,"by_line":{"AGATA":{"active":14,"active_instock":10,"active_oos":4},"AIRPODS":{"active":6,"active_instock":6,"active_oos":0},"ANNIE":{"active":11,"active_instock":7,"active_oos":4},"GIFT":{"active":1,"active_instock":0,"active_oos":1},"LAPTOP":{"active":7,"active_instock":7,"active_oos":0},"LEA":{"active":20,"active_instock":15,"active_oos":5},"MARIA":{"active":2,"active_instock":2,"active_oos":0},"MINI":{"active":6,"active_instock":6,"active_oos":0},"NINA":{"active":16,"active_instock":16,"active_oos":0},"SUNGLASS":{"active":6,"active_instock":6,"active_oos":0},"TIGER":{"active":1,"active_instock":1,"active_oos":0},"VALENTINA":{"active":4,"active_instock":4,"active_oos":0}},"by_macro":{"Tessuto":{"active":41,"active_instock":33,"active_oos":8},"Pelle":{"active":26,"active_instock":21,"active_oos":5},"Accessori":{"active":26,"active_instock":26,"active_oos":0},"Altro":{"active":1,"active_instock":0,"active_oos":1}}}
A8: 46186.912 | B8: 46186 | C8: {"ts":"2026-06-13 21:54","date":"2026-06-13","total":214,"active":94,"draft":120,"archived":0,"active_instock":79,"active_oos":15,"instock_not_active":2,"var_active_instock":99,"by_line":{"AGATA":{"active":14,"active_instock":10,"active_oos":4},"AIRPODS":{"active":6,"active_instock":6,"active_oos":0},"ANNIE":{"active":11,"active_instock":6,"active_oos":5},"GIFT":{"active":1,"active_instock":0,"active_oos":1},"LAPTOP":{"active":7,"active_instock":7,"active_oos":0},"LEA":{"active":20,"active_instock":15,"active_oos":5},"MARIA":{"active":2,"active_instock":2,"active_oos":0},"MINI":{"active":6,"active_instock":6,"active_oos":0},"NINA":{"active":16,"active_instock":16,"active_oos":0},"SUNGLASS":{"active":6,"active_instock":6,"active_oos":0},"TIGER":{"active":1,"active_instock":1,"active_oos":0},"VALENTINA":{"active":4,"active_instock":4,"active_oos":0}},"by_macro":{"Tessuto":{"active":41,"active_instock":32,"active_oos":9},"Pelle":{"active":26,"active_instock":21,"active_oos":5},"Accessori":{"active":26,"active_instock":26,"active_oos":0},"Altro":{"active":1,"active_instock":0,"active_oos":1}}}
A9: 46187.559 | B9: 46187 | C9: {"ts":"2026-06-14 13:25","date":"2026-06-14","total":214,"active":94,"draft":120,"archived":0,"active_instock":75,"active_oos":19,"instock_not_active":2,"var_active_instock":92,"by_line":{"AGATA":{"active":14,"active_instock":8,"active_oos":6},"AIRPODS":{"active":6,"active_instock":6,"active_oos":0},"ANNIE":{"active":11,"active_instock":5,"active_oos":6},"GIFT":{"active":1,"active_instock":0,"active_oos":1},"LAPTOP":{"active":7,"active_instock":7,"active_oos":0},"LEA":{"active":20,"active_instock":14,"active_oos":6},"MARIA":{"active":2,"active_instock":2,"active_oos":0},"MINI":{"active":6,"active_instock":6,"active_oos":0},"NINA":{"active":16,"active_instock":16,"active_oos":0},"SUNGLASS":{"active":6,"active_instock":6,"active_oos":0},"TIGER":{"active":1,"active_instock":1,"active_oos":0},"VALENTINA":{"active":4,"active_instock":4,"active_oos":0}},"by_macro":{"Tessuto":{"active":41,"active_instock":29,"active_oos":12},"Pelle":{"active":26,"active_instock":20,"active_oos":6},"Accessori":{"active":26,"active_instock":26,"active_oos":0},"Altro":{"active":1,"active_instock":0,"active_oos":1}}}
A10: 46188.559 | B10: 46188 | C10: {"ts":"2026-06-15 13:25","date":"2026-06-15","total":214,"active":94,"draft":120,"archived":0,"active_instock":76,"active_oos":18,"instock_not_active":2,"var_active_instock":94,"by_line":{"AGATA":{"active":14,"active_instock":8,"active_oos":6},"AIRPODS":{"active":6,"active_instock":6,"active_oos":0},"ANNIE":{"active":11,"active_instock":6,"active_oos":5},"GIFT":{"active":1,"active_instock":0,"active_oos":1},"LAPTOP":{"active":7,"active_instock":7,"active_oos":0},"LEA":{"active":20,"active_instock":14,"active_oos":6},"MARIA":{"active":2,"active_instock":2,"active_oos":0},"MINI":{"active":6,"active_instock":6,"active_oos":0},"NINA":{"active":16,"active_instock":16,"active_oos":0},"SUNGLASS":{"active":6,"active_instock":6,"active_oos":0},"TIGER":{"active":1,"active_instock":1,"active_oos":0},"VALENTINA":{"active":4,"active_instock":4,"active_oos":0}},"by_macro":{"Tessuto":{"active":41,"active_instock":30,"active_oos":11},"Pelle":{"active":26,"active_instock":20,"active_oos":6},"Accessori":{"active":26,"active_instock":26,"active_oos":0},"Altro":{"active":1,"active_instock":0,"active_oos":1}}}
A11: 46189.559 | B11: 46189 | C11: {"ts":"2026-06-16 13:25","date":"2026-06-16","total":214,"active":94,"draft":120,"archived":0,"active_instock":76,"active_oos":18,"instock_not_active":2,"var_active_instock":94,"by_line":{"AGATA":{"active":14,"active_instock":8,"active_oos":6},"AIRPODS":{"active":6,"active_instock":6,"active_oos":0},"ANNIE":{"active":11,"active_instock":6,"active_oos":5},"GIFT":{"active":1,"active_instock":0,"active_oos":1},"LAPTOP":{"active":7,"active_instock":7,"active_oos":0},"LEA":{"active":20,"active_instock":14,"active_oos":6},"MARIA":{"active":2,"active_instock":2,"active_oos":0},"MINI":{"active":6,"active_instock":6,"active_oos":0},"NINA":{"active":16,"active_instock":16,"active_oos":0},"SUNGLASS":{"active":6,"active_instock":6,"active_oos":0},"TIGER":{"active":1,"active_instock":1,"active_oos":0},"VALENTINA":{"active":4,"active_instock":4,"active_oos":0}},"by_macro":{"Tessuto":{"active":41,"active_instock":30,"active_oos":11},"Pelle":{"active":26,"active_instock":20,"active_oos":6},"Accessori":{"active":26,"active_instock":26,"active_oos":0},"Altro":{"active":1,"active_instock":0,"active_oos":1}}}
A12: 46190.559 | B12: 46190 | C12: {"ts":"2026-06-17 13:25","date":"2026-06-17","total":214,"active":94,"draft":120,"archived":0,"active_instock":75,"active_oos":19,"instock_not_active":2,"var_active_instock":92,"by_line":{"AGATA":{"active":14,"active_instock":6,"active_oos":8},"AIRPODS":{"active":6,"active_instock":6,"active_oos":0},"ANNIE":{"active":11,"active_instock":7,"active_oos":4},"GIFT":{"active":1,"active_instock":0,"active_oos":1},"LAPTOP":{"active":7,"active_instock":7,"active_oos":0},"LEA":{"active":20,"active_instock":14,"active_oos":6},"MARIA":{"active":2,"active_instock":2,"active_oos":0},"MINI":{"active":6,"active_instock":6,"active_oos":0},"NINA":{"active":16,"active_instock":16,"active_oos":0},"SUNGLASS":{"active":6,"active_instock":6,"active_oos":0},"TIGER":{"active":1,"active_instock":1,"active_oos":0},"VALENTINA":{"active":4,"active_instock":4,"active_oos":0}},"by_macro":{"Tessuto":{"active":41,"active_instock":29,"active_oos":12},"Pelle":{"active":26,"active_instock":20,"active_oos":6},"Accessori":{"active":26,"active_instock":26,"active_oos":0},"Altro":{"active":1,"active_instock":0,"active_oos":1}}}
A13: 46191.559 | B13: 46191 | C13: {"ts":"2026-06-18 13:25","date":"2026-06-18","total":214,"active":94,"draft":120,"archived":0,"active_instock":76,"active_oos":18,"instock_not_active":2,"var_active_instock":90,"by_line":{"AGATA":{"active":14,"active_instock":6,"active_oos":8},"AIRPODS":{"active":6,"active_instock":6,"active_oos":0},"ANNIE":{"active":11,"active_instock":8,"active_oos":3},"GIFT":{"active":1,"active_instock":0,"active_oos":1},"LAPTOP":{"active":7,"active_instock":7,"active_oos":0},"LEA":{"active":20,"active_instock":14,"active_oos":6},"MARIA":{"active":2,"active_instock":2,"active_oos":0},"MINI":{"active":6,"active_instock":6,"active_oos":0},"NINA":{"active":16,"active_instock":16,"active_oos":0},"SUNGLASS":{"active":6,"active_instock":6,"active_oos":0},"TIGER":{"active":1,"active_instock":1,"active_oos":0},"VALENTINA":{"active":4,"active_instock":4,"active_oos":0}},"by_macro":{"Tessuto":{"active":41,"active_instock":30,"active_oos":11},"Pelle":{"active":26,"active_instock":20,"active_oos":6},"Accessori":{"active":26,"active_instock":26,"active_oos":0},"Altro":{"active":1,"active_instock":0,"active_oos":1}}}
... A27: 46205.559 | B27: 46205 | C27: {"ts":"2026-07-02 13:25","date":"2026-07-02","total":218,"active":93,"draft":125,"archived":0,"active_instock":71,"active_oos":22,"instock_not_active":2,"var_active_instock":80,"by_line":{"AGATA":{"active":16,"active_instock":5,"active_oos":11},"AIRPODS":{"active":6,"active_instock":6,"active_oos":0},"ANNIE":{"active":10,"active_instock":4,"active_oos":6},"GIFT":{"active":1,"active_instock":0,"active_oos":1},"LAPTOP":{"active":7,"active_instock":7,"active_oos":0},"LEA":{"active":15,"active_instock":11,"active_oos":4},"MARIA":{"active":5,"active_instock":5,"active_oos":0},"MINI":{"active":6,"active_instock":6,"active_oos":0},"NINA":{"active":16,"active_instock":16,"active_oos":0},"SUNGLASS":{"active":6,"active_instock":6,"active_oos":0},"TIGER":{"active":1,"active_instock":1,"active_oos":0},"VALENTINA":{"active":4,"active_instock":4,"active_oos":0}},"by_macro":{"Tessuto":{"active":42,"active_instock":25,"active_oos":17},"Pelle":{"active":24,"active_instock":20,"active_oos":4},"Accessori":{"active":26,"active_instock":26,"active_oos":0},"Altro":{"active":1,"active_instock":0,"active_oos":1}}}

Sheet CATALOG_SYNC_V2
A1: Product_Name | B1: Product_ID | C1: Variant_ID | D1: InventoryItem_ID | E1: Location_ID | F1: CODICE_AMIIMI | G1: Note | H1: Handle | I1: SKIP | J1: CONTA_VERIFICATA
A2: AIRPODS CASE CANDY PINK | B2: gid://shopify/Product/10795764023623 | C2: gid://shopify/ProductVariant/53909681406279 | D2: gid://shopify/InventoryItem/55500846301511 | E2: gid://shopify/Location/107986518343 | F2: Airpod_Cover_7X9_STRIPES_CANDY_PINK | H2: airpods-case-stripes-pink-olive
A3: AIRPODS CASE CHERRY PINK | B3: gid://shopify/Product/10795764220231 | C3: gid://shopify/ProductVariant/53909681701191 | D3: gid://shopify/InventoryItem/55500846596423 | E3: gid://shopify/Location/107986518343 | F3: Airpod_Cover_7X9_CHECKS_CHERRY_PINK | H3: airpods-case-checks-cherry-pink
A4: AIRPODS CASE FOREST GREEN | B4: gid://shopify/Product/10795764252999 | C4: gid://shopify/ProductVariant/53909681733959 | D4: gid://shopify/InventoryItem/55500846629191 | E4: gid://shopify/Location/107986518343 | F4: Airpod_Cover_7X9_CHECKS_FOREST_GREEN | H4: airpods-case-checks-olive-cream
A5: AIRPODS CASE LIGHT BLUE | B5: gid://shopify/Product/10795764154695 | C5: gid://shopify/ProductVariant/53909681602887 | D5: gid://shopify/InventoryItem/55500846498119 | E5: gid://shopify/Location/107986518343 | F5: Airpod_Cover_7X9_STRIPES_LIGHT_BLUE | H5: airpods-case-stripes-azure-red
A6: AIRPODS CASE LIME PINK | B6: gid://shopify/Product/10795763990855 | C6: gid://shopify/ProductVariant/53909681373511 | D6: gid://shopify/InventoryItem/55500846268743 | E6: gid://shopify/Location/107986518343 | F6: Airpod_Cover_7X9_STRIPES_LIME_PINK | H6: airpods-case-stripes-mustard-rose
A7: AIRPODS CASE RED | B7: gid://shopify/Product/10795764121927 | C7: gid://shopify/ProductVariant/53909681570119 | D7: gid://shopify/InventoryItem/55500846465351 | E7: gid://shopify/Location/107986518343 | F7: Airpod_Cover_7X9_STRIPES_RED | H7: airpods-case-stripes-reed
A8: LAPTOP COVER CANDY PINK | B8: gid://shopify/Product/10795763564871 | C8: gid://shopify/ProductVariant/53909680750919 | D8: gid://shopify/InventoryItem/55500845646151 | E8: gid://shopify/Location/107986518343 | F8: Laptop_Cover_26X37_STRIPES_CANDY_PINK | H8: laptop-cover-stripes-pink-olive
A9: LAPTOP COVER CHECKS ORANGE | B9: gid://shopify/Product/10795763794247 | C9: gid://shopify/ProductVariant/53909681209671 | D9: gid://shopify/InventoryItem/55500846104903 | E9: gid://shopify/Location/107986518343 | F9: Laptop_Cover_26X37_CHECKS_ORANGE | H9: laptop-cover-checks-cherry-yellow
A10: LAPTOP COVER CHERRY PINK | B10: gid://shopify/Product/10795763695943 | C10: gid://shopify/ProductVariant/53909681013063 | D10: gid://shopify/InventoryItem/55500845908295 | E10: gid://shopify/Location/107986518343 | F10: Laptop_Cover_26X37_STRIPES_CHERRY_PINK | H10: laptop-cover-stripes-cherry-pink
A11: LAPTOP COVER FOREST GREEN | B11: gid://shopify/Product/10795763761479 | C11: gid://shopify/ProductVariant/53909681078599 | D11: gid://shopify/InventoryItem/55500845973831 | E11: gid://shopify/Location/107986518343 | F11: Laptop_Cover_26X37_STRIPES_FOREST_GREEN | H11: laptop-cover-stripes-olive-cream
A12: LAPTOP COVER LIGHT BLUE | B12: gid://shopify/Product/10795763663175 | C12: gid://shopify/ProductVariant/53909680980295 | D12: gid://shopify/InventoryItem/55500845875527 | E12: gid://shopify/Location/107986518343 | F12: Laptop_Cover_26X37_STRIPES_LIGHT_BLUE | H12: laptop-cover-stripes-azure-red
A13: LAPTOP COVER LIME PINK | B13: gid://shopify/Product/10795763466567 | C13: gid://shopify/ProductVariant/53909680652615 | D13: gid://shopify/InventoryItem/55500845547847 | E13: gid://shopify/Location/107986518343 | F13: Laptop_Cover_26X37_STRIPES_LIME_PINK | H13: laptop-cover-stripes-mustard-rose
A14: LAPTOP COVER RED | B14: gid://shopify/Product/10795763630407 | C14: gid://shopify/ProductVariant/53909680849223 | D14: gid://shopify/InventoryItem/55500845744455 | E14: gid://shopify/Location/107986518343 | F14: Laptop_Cover_26X37_STRIPES_RED | H14: laptop-cover-stripes-reed
A15: LEA BAG BLACK COCCO | B15: gid://shopify/Product/10606557659463 | C15: gid://shopify/ProductVariant/53147874820423 | D15: gid://shopify/InventoryItem/54729895018823 | E15: gid://shopify/Location/107986518343 | F15: Lea_Bag_COCCO_BLACK | H15: lea-bag-cocco-black | J15: 46182.625
A16: LEA BAG BLACK PONY | B16: gid://shopify/Product/10606560084295 | C16: gid://shopify/ProductVariant/53147885240647 | D16: gid://shopify/InventoryItem/54729905275207 | E16: gid://shopify/Location/107986518343 | F16: Lea_Bag_BLACK | H16: lea-bag-black
A17: LEA BAG COCCO BEIGE | B17: gid://shopify/Product/10801084105031 | C17: gid://shopify/ProductVariant/53934512570695 | D17: gid://shopify/InventoryItem/55525765316935 | E17: gid://shopify/Location/107986518343 | F17: Lea_Bag_COCCO_BEIGE | H17: lea-bag-cocco-beige | J17: 46182.625
A18: LEA BAG COCCO GREEN | B18: gid://shopify/Product/10801085153607 | C18: gid://shopify/ProductVariant/53934518534471 | D18: gid://shopify/InventoryItem/55525771280711 | E18: gid://shopify/Location/107986518343 | F18: Lea_Bag_COCCO_GREEN | H18: lea-bag-cocco-green
A19: LEA BAG COCCO PINK | B19: gid://shopify/Product/10801084989767 | C19: gid://shopify/ProductVariant/53934518272327 | D19: gid://shopify/InventoryItem/55525771018567 | E19: gid://shopify/Location/107986518343 | F19: Lea_Bag_COCCO_PINK | H19: lea-bag-cocco-pink | J19: 46182.625
A20: LEA BAG COCCO PURPLE | B20: gid://shopify/Product/10801084629319 | C20: gid://shopify/ProductVariant/53934515290439 | D20: gid://shopify/InventoryItem/55525768036679 | E20: gid://shopify/Location/107986518343 | F20: Lea_Bag_COCCO_PURPLE | H20: lea-bag-cocco-purple | J20: 46182.625
A21: LEA BAG DARK ZEBRA PONY | B21: gid://shopify/Product/10606554874183 | C21: gid://shopify/ProductVariant/53147865547079 | D21: gid://shopify/InventoryItem/54729885909319 | E21: gid://shopify/Location/107986518343 | F21: Lea_Bag_Zebra_Dark | H21: lea-bag-dark-zebra-1 | J21: 46182.625
A22: LEA BAG LIGHT BROWN PONY | B22: gid://shopify/Product/10606560641351 | C22: gid://shopify/ProductVariant/53147885994311 | D22: gid://shopify/InventoryItem/54729905996103 | E22: gid://shopify/Location/107986518343 | F22: Lea_Bag_Cavallino_Light_Brown | H22: lea-bag-marron-chocolate | J22: 46182.625
A23: LEA BAG MAXI COCCO BLACK | B23: gid://shopify/Product/10695941652807 | C23: gid://shopify/ProductVariant/53495138058567 | D23: gid://shopify/InventoryItem/55079187611975 | E23: gid://shopify/Location/107986518343 | F23: Lea_Bag_Maxi_COCCO_BLACK | H23: lea-bag-maxi-cocco-black | J23: 46182.625
A24: LEA BAG MAXI COCCO CHOCOLATE | B24: gid://shopify/Product/10801081811271 | C24: gid://shopify/ProductVariant/53934503297351 | D24: gid://shopify/InventoryItem/55525756043591 | E24: gid://shopify/Location/107986518343 | F24: Lea_Bag_Maxi_COCCO_CHOCOLATE | H24: lea-bag-maxi-cocco-chocolate
A25: LEA BAG MAXI SUEDE CHOCOLATE | B25: gid://shopify/Product/10695954596167 | C25: gid://shopify/ProductVariant/53495186784583 | D25: gid://shopify/InventoryItem/55079238041927 | E25: gid://shopify/Location/107986518343 | F25: Lea_Bag_Maxi_SUEDE_CHOCOLATE | H25: lea-bag-maxi-suede-chocolate
A26: LEA BAG MAXI SUEDE CHOCOLATE CHARM | B26: gid://shopify/Product/10695962362183 | C26: gid://shopify/ProductVariant/53495234134343 | D26: gid://shopify/InventoryItem/55079286309191 | E26: gid://shopify/Location/107986518343 | F26: Lea_Bag_Maxi_SUEDE_CHOCOLATE_CHARM | H26: lea-bag-maxi-suede-chocolate-charm | J26: 46182.625
A27: LEA BAG RED PATENT | B27: gid://shopify/Product/10606559625543 | C27: gid://shopify/ProductVariant/53147884519751 | D27: gid://shopify/InventoryItem/54729904685383 | E27: gid://shopify/Location/107986518343 | F27: Lea_Bag_RED_PATENT | H27: lea-bag-vernice-rosso | J27: 46182.625
A28: LEA BAG SAVANA LEOPARD PONY | B28: gid://shopify/Product/10606560674119 | C28: gid://shopify/ProductVariant/53147886027079 | D28: gid://shopify/InventoryItem/54729906028871 | E28: gid://shopify/Location/107986518343 | F28: Lea_Bag_LEOPARDO_SAVANA | H28: lea-bag-leopardo | J28: 46182.625
A29: LEA BAG VERNICE PURPLE PATENT | B29: gid://shopify/Product/10606559035719 | C29: gid://shopify/ProductVariant/53147880587591 | D29: gid://shopify/InventoryItem/54729900753223 | E29: gid://shopify/Location/107986518343 | F29: Lea_Bag_VERNICE_PURPLE_PATENT | H29: lea-bag-vernice-viola-malva | J29: 46182.625
A30: MARIA BAG BLACK PIERCING | B30: gid://shopify/Product/10868713947463 | C30: gid://shopify/ProductVariant/54213275517255 | D30: gid://shopify/InventoryItem/55808339050823 | E30: gid://shopify/Location/107986518343 | F30: Maria_Bag_BLACK_PIERCING | H30: maria-bag-black-piercing
A31: MARIA BAG BURRO PIERCING | B31: gid://shopify/Product/10801086366023 | C31: gid://shopify/ProductVariant/53934519648583 | D31: gid://shopify/InventoryItem/55525772394823 | E31: gid://shopify/Location/107986518343 | F31: Maria_Bag_BURRO_PIERCING | H31: maria-bag-burro-piercing
A32: MARIA BAG GREEN PIERCING | B32: gid://shopify/Product/10868713619783 | C32: gid://shopify/ProductVariant/54213275091271 | D32: gid://shopify/InventoryItem/55808338624839 | E32: gid://shopify/Location/107986518343 | F32: Maria_Bag_GREEN_PIERCING | H32: maria-bag-green-piercing
A33: MARIA BAG ICE BLUE PIERCING | B33: gid://shopify/Product/10868713849159 | C33: gid://shopify/ProductVariant/54213275418951 | D33: gid://shopify/InventoryItem/55808338952519 | E33: gid://shopify/Location/107986518343 | F33: Maria_Bag_ICE_BLUE_PIERCING | H33: maria-bag-ice-blue-piercing
A34: MARIA BAG RED PIERCING | B34: gid://shopify/Product/10655260410183 | C34: gid://shopify/ProductVariant/53347013067079 | D34: gid://shopify/InventoryItem/54930251317575 | E34: gid://shopify/Location/107986518343 | F34: Maria_Bag_RED_PIERCING | H34: maria-bag-bordeaux | J34: 46182.625
A35: MINI CASE CANDY PINK | B35: gid://shopify/Product/10795764351303 | C35: gid://shopify/ProductVariant/53909682323783 | D35: gid://shopify/InventoryItem/55500847219015 | E35: gid://shopify/Location/107986518343 | F35: Airpod_Cover_9X11_STRIPES_CANDY_PINK | H35: mini-case-stripes-pink-olive
A36: MINI CASE CHERRY PINK | B36: gid://shopify/Product/10795764482375 | C36: gid://shopify/ProductVariant/53909682422087 | D36: gid://shopify/InventoryItem/55500847317319 | E36: gid://shopify/Location/107986518343 | F36: Airpod_Cover_9X11_CHECKS_CHERRY_PINK | H36: mini-case-checks-cherry-pink
A37: MINI CASE FOREST GREEN | B37: gid://shopify/Product/10795764613447 | C37: gid://shopify/ProductVariant/53909682553159 | D37: gid://shopify/InventoryItem/55500847448391 | E37: gid://shopify/Location/107986518343 | F37: Airpod_Cover_9X11_CHECKS_FOREST_GREEN | H37: mini-case-checks-olive-cream
A38: MINI CASE LIGHT BLUE | B38: gid://shopify/Product/10795764449607 | C38: gid://shopify/ProductVariant/53909682389319 | D38: gid://shopify/InventoryItem/55500847284551 | E38: gid://shopify/Location/107986518343 | F38: Airpod_Cover_9X11_STRIPES_LIGHT_BLUE | H38: mini-case-stripes-azure-red
A39: MINI CASE LIME PINK | B39: gid://shopify/Product/10795764285767 | C39: gid://shopify/ProductVariant/53909682258247 | D39: gid://shopify/InventoryItem/55500847153479 | E39: gid://shopify/Location/107986518343 | F39: Airpod_Cover_9X11_STRIPES_LIME_PINK | H39: mini-case-stripes-mustard-rose
A40: MINI CASE RED | B40: gid://shopify/Product/10795764384071 | C40: gid://shopify/ProductVariant/53909682356551 | D40: gid://shopify/InventoryItem/55500847251783 | E40: gid://shopify/Location/107986518343 | F40: Airpod_Cover_9X11_STRIPES_RED | H40: mini-case-stripes-reed
...

Sheet VARIANT_SYNC_V2_LOG
A1: Timestamp | B1: Type | C1: Bag | D1: Detail
A2: 46181.557 | B2: BUILD_MAP_V2 | D2: VARIANT_SYNC_V2 built: 23 bags, 0 senza CODICE risolto
A3: 46181.558 | B3: BUILD_MAP_V2 | D3: VARIANT_SYNC_V2 built: 23 bags, 0 senza CODICE risolto
A4: 46181.559 | B4: SIMULATE | C4: AGATA BAG FLORAL BORDEAUX EMBROIDERY | D4: 1 -> 2 (Agata_Bag_FLORAL_BORDEAUX_EMBROIDERY)
A5: 46181.559 | B5: SIMULATE | C5: AGATA BAG FLORAL DUSTY PINK EMBROIDERY | D5: 3 -> 5 (Agata_Bag_FLORAL_DUSTY_PINK_EMBROIDERY)
A6: 46181.559 | B6: SIMULATE | C6: AGATA BAG FLORAL GREEN EMBROIDERY | D6: 0 -> 1 (Agata_Bag_FLORAL_GREEN_EMBROIDERY)
A7: 46181.559 | B7: SKIP_NOT_IN_INV | C7: AGATA BAG FLORAL ORANGE EMBROIDERY | D7: CODICE Agata_Bag_floral_orange_embroidery assente in INVENTARIO
A8: 46181.559 | B8: CLAMP_NEG | C8: AGATA BAG FLORAL PINK EMBROIDERY | D8: INVENTARIO -2 -> 0 (Agata_Bag_FLORAL_PINK_EMBROIDERY)
A9: 46181.559 | B9: SIMULATE | C9: AGATA BAG PAILLETTES PINK | D9: 1 -> 9 (Agata_Bag_PAILLETTES_PINK)
A10: 46181.559 | B10: SIMULATE | C10: AGATA BAG ROSE PINK | D10: 1 -> 3 (Agata_Bag_ROSE_PINK)
A11: 46181.559 | B11: SIMULATE | C11: AGATA BAG TIE DYE PINK | D11: 3 -> 4 (Agata_Bag_TIE_DYE_PINK)
A12: 46181.559 | B12: SIMULATE | C12: ANNIE BAG BLUE | D12: 1 -> 7 (Annie_Bag_BLUE)
A13: 46181.559 | B13: SKIP_NOT_IN_INV | C13: ANNIE BAG LILAC | D13: CODICE Annie_Bag_LILAC assente in INVENTARIO
A14: 46181.559 | B14: SIMULATE | C14: ANNIE BAG PAILLETTES LIGHT BLUE | D14: 0 -> 5 (Annie_Bag_PAILLETTES_LIGHT_BLUE)
A15: 46181.559 | B15: SIMULATE | C15: ANNIE BAG PAILLETTES LIGHT GREEN | D15: 0 -> 1 (Annie_Bag_PAILLETTES_LIGHT_GREEN)
... A22: 46181.559 | B22: SKIP_NOT_IN_INV | C22: ANNIE BAG STRIPES PINK | D22: CODICE Annie_Bag_STRIPES_PINK assente in INVENTARIO
A23: 46181.559 | B23: RECONCILE_DONE | D23: [DRY-RUN] reconcile V2 — simulate=12, noop=7, skip=3, flagged=1, errors=0
A24: 46181.676 | B24: FLAG_VERIFICA2 | C24: AGATA BAG FLORAL BORDEAUX EMBROIDERY | D24: gestionale 2 -> sito 1 (Agata_Bag_FLORAL_BORDEAUX_EMBROIDERY)
A25: 46181.676 | B25: FLAG_VERIFICA2 | C25: AGATA BAG FLORAL GREY | D25: gestionale 2 -> sito 1 (Agata_Bag_FLORAL_GREY)
A26: 46181.676 | B26: SKIP_NOT_IN_INV | C26: AGATA BAG FLORAL ORANGE EMBROIDERY | D26: CODICE Agata_Bag_floral_orange_embroidery assente in INVENTARIO
A27: 46181.676 | B27: FLAG_NEGATIVO | C27: AGATA BAG FLORAL PINK EMBROIDERY | D27: gestionale -2 -> sito 0 (Agata_Bag_FLORAL_PINK_EMBROIDERY)
A28: 46181.676 | B28: CHANGE_SKIPPED | C28: AGATA BAG PAILLETTES PINK | D28: sito 1 -> 7 (delta 6) — safe-mode: NON applicato, rivedi
A29: 46181.676 | B29: FLAG_VERIFICA2 | C29: AGATA BAG ROSE BLUE | D29: gestionale 2 -> sito 1 (Agata_Bag_ROSE_BLUE)
A30: 46181.676 | B30: SET | C30: AGATA BAG ROSE BLUE | D30: 2 -> 1
A31: 46181.676 | B31: FLAG_VERIFICA2 | C31: AGATA BAG ROSE BUTTER | D31: gestionale 2 -> sito 1 (Agata_Bag_ROSE_BUTTER)
A32: 46181.676 | B32: SET | C32: AGATA BAG ROSE BUTTER | D32: 2 -> 1
A33: 46181.676 | B33: SET | C33: AGATA BAG ROSE BUTTER GREEN | D33: 5 -> 3
A34: 46181.676 | B34: SET | C34: AGATA BAG TIE DYE PINK | D34: 3 -> 2
A35: 46181.676 | B35: CHANGE_SKIPPED | C35: ANNIE BAG BLUE | D35: sito 1 -> 5 (delta 4) — safe-mode: NON applicato, rivedi
... A43: 46181.676 | B43: SKIP_NOT_IN_INV | C43: ANNIE BAG STRIPES PINK | D43: CODICE Annie_Bag_STRIPES_PINK assente in INVENTARIO
A44: 46181.676 | B44: RECONCILE_DONE | D44: [APPLY] reconcile V2 — set=4, noop=10, skip=3, flagged=6, errors=0
A45: 46181.696 | B45: FLAG_VERIFICA2 | C45: AGATA BAG FLORAL BORDEAUX EMBROIDERY | D45: gestionale 2 -> sito 1 (Agata_Bag_FLORAL_BORDEAUX_EMBROIDERY)
